Workbook

Sheet LISTA GESTANTE DO GOOGLE FORMS
A1: Nº de Mães | B1: Nº na Lista da Secretaria | C1: Carimbo de data/hora | D1: Nome Completo da Gestante | E1: Telefone com DDD e WHATSAPP | F1: Idade Gestacional | G1: Data Provável do Parto | H1: Sexo da Criança | I1: CPF da Gestante | J1: Nº da Identidade da Gestante | K1: Data de Nascimento da Gestante | L1: Idade da Gestante | M1: Está Trabalhando | N1: Estado Civil | O1: Religião | P1: Observações | Q1: Endereço Completo (Rua, Nº e Complemento) | R1: Bairro | S1: Cidade | T1: Nome Completo do Pai da Criança | U1: Nº de Pessoas na Casa | V1: Precisa de Atendimento Profissional | W1: Recebe Benefício do Governo | X1: e-mail da Gestante | Y1: Responsável pelo Cadastro
A2: 1 | B2: 1347 | C2: 45902.369 | D2: Stephanie Lorrayne dos Santos Freitas | E2: (31) 99282-4775 | F2: 7º Mês | G2: 45969 | H2: Menina | I2: 124.527.806-18 | J2: MG 23.145.828 | K2: 36883 | L2: 25 | M2: Não | N2: União Estável | O2: Evangélica | P2: Gestante Antecipada para Outubro para compor o evento | Q2: Avenida Jeferson Coelho da Silva, 369 - Bloco 2 Apt 401 | R2: Parque Estrela do Sul | S2: Ribeirão das Neves | T2: Stephanie Lorrayne dos Santos Freitas | U2: 1 NP | V2: Psicólogo | W2: Bolsa Família | X2: josecarlos1990@gmail.com | Y2: João
A3: =A2+1 -> 2 | C3: 2 | D3: 2 nome da gestante | E3: 2 telefone | F3: 2 gest | G3: 2 parto | H3: 2 sexo | I3: 2 cpf | J3: 2 identidade | K3: 2 D Nascim | L3: 2 idad | M3: 2 trab | N3: 2 Est Civil | O3: 2 Religiao | P3: 2 Observações | Q3: 2 Endereço | R3: 2 Bairro | S3: 2 cidade | T3: 2 nome do pai | U3: 2 NP | V3: 2 Atendim | W3: 2 Beneficio | X3: 2 email | Y3: 2 joao
A4: =A3+1 -> 3 | C4: =C3+1 -> 3 | D4: 3 nome da gestante | E4: 3 telefone | F4: 3 gest | G4: 3 parto | H4: 3 sexo | I4: 3 cpf | J4: 3 identidade | K4: 3 D Nascim | L4: 3 idad | M4: 3 trab | N4: 3 Est Civil | O4: 3 Religiao | P4: 3 Observações | Q4: 3 Endereço | R4: 3 Bairro | S4: 3 cidade | T4: 3 nome do pai | U4: 3 NP | V4: 3 Atendim | W4: 3 Beneficio | X4: 3 email | Y4: 3 joao
A5: =A4+1 -> 4 | C5: =C4+1 -> 4 | D5: 4 nome da gestante | E5: 4 telefone | F5: 4 gest | G5: 4 parto | H5: 4 sexo | I5: 4 cpf | J5: 4 identidade | K5: 4 D Nascim | L5: 4 idad | M5: 4 trab | N5: 4 Est Civil | O5: 4 Religiao | P5: 4 Observações | Q5: 4 Endereço | R5: 4 Bairro | S5: 4 cidade | T5: 4 nome do pai | U5: 4 NP | V5: 4 Atendim | W5: 4 Beneficio | X5: 4 email | Y5: 4 joao
A6: =A5+1 -> 5 | C6: =C5+1 -> 5 | D6: 5 nome da gestante | E6: 5 telefone | F6: 5 gest | G6: 5 parto | H6: 5 sexo | I6: 5 cpf | J6: 5 identidade | K6: 5 D Nascim | L6: 5 idad | M6: 5 trab | N6: 5 Est Civil | O6: 5 Religiao | P6: 5 Observações | Q6: 5 Endereço | R6: 5 Bairro | S6: 5 cidade | T6: 5 nome do pai | U6: 5 NP | V6: 5 Atendim | W6: 5 Beneficio | X6: 5 email | Y6: 5 joao
A7: =A6+1 -> 6 | C7: =C6+1 -> 6 | D7: 6 nome da gestante | E7: 6 telefone | F7: 6 gest | G7: 6 parto | H7: 6 sexo | I7: 6 cpf | J7: 6 identidade | K7: 6 D Nascim | L7: 6 idad | M7: 6 trab | N7: 6 Est Civil | O7: 6 Religiao | P7: 6 Observações | Q7: 6 Endereço | R7: 6 Bairro | S7: 6 cidade | T7: 6 nome do pai | U7: 6 NP | V7: 6 Atendim | W7: 6 Beneficio | X7: 6 email | Y7: 6 joao
A8: =A7+1 -> 7 | C8: =C7+1 -> 7 | D8: 7 nome da gestante | E8: 7 telefone | F8: 7 gest | G8: 7 parto | H8: 7 sexo | I8: 7 cpf | J8: 7 identidade | K8: 7 D Nascim | L8: 7 idad | M8: 7 trab | N8: 7 Est Civil | O8: 7 Religiao | P8: 7 Observações | Q8: 7 Endereço | R8: 7 Bairro | S8: 7 cidade | T8: 7 nome do pai | U8: 7 NP | V8: 7 Atendim | W8: 7 Beneficio | X8: 7 email | Y8: 7 joao
A9: =A8+1 -> 8 | C9: =C8+1 -> 8 | D9: 8 nome da gestante | E9: 8 telefone | F9: 8 gest | G9: 8 parto | H9: 8 sexo | I9: 8 cpf | J9: 8 identidade | K9: 8 D Nascim | L9: 8 idad | M9: 8 trab | N9: 8 Est Civil | O9: 8 Religiao | P9: 8 Observações | Q9: 8 Endereço | R9: 8 Bairro | S9: 8 cidade | T9: 8 nome do pai | U9: 8 NP | V9: 8 Atendim | W9: 8 Beneficio | X9: 8 email | Y9: 8 joao
A10: =A9+1 -> 9 | C10: =C9+1 -> 9 | D10: 9 nome da gestante | E10: 9 telefone | F10: 9 gest | G10: 9 parto | H10: 9 sexo | I10: 9 cpf | J10: 9 identidade | K10: 9 D Nascim | L10: 9 idad | M10: 9 trab | N10: 9 Est Civil | O10: 9 Religiao | P10: 9 Observações | Q10: 9 Endereço | R10: 9 Bairro | S10: 9 cidade | T10: 9 nome do pai | U10: 9 NP | V10: 9 Atendim | W10: 9 Beneficio | X10: 9 email | Y10: 9 joao
A11: =A10+1 -> 10 | C11: =C10+1 -> 10 | D11: 10 nome da gestante | E11: 10 telefone | F11: 10 gest | G11: 10 parto | H11: 10 sexo | I11: 10 cpf | J11: 10 identidade | K11: 10 D Nascim | L11: 10 idad | M11: 10 trab | N11: 10 Est Civil | O11: 10 Religiao | P11: 10 Observações | Q11: 10 Endereço | R11: 10 Bairro | S11: 10 cidade | T11: 10 nome do pai | U11: 10 NP | V11: 10 Atendim | W11: 10 Beneficio | X11: 10 email | Y11: 10 joao
A12: =A11+1 -> 11 | C12: =C11+1 -> 11 | D12: 11 nome da gestante | E12: 11 telefone | F12: 11 gest | G12: 11 parto | H12: 11 sexo | I12: 11 cpf | J12: 11 identidade | K12: 11 D Nascim | L12: 11 idad | M12: 11 trab | N12: 11 Est Civil | O12: 11 Religiao | P12: 11 Observações | Q12: 11 Endereço | R12: 11 Bairro | S12: 11 cidade | T12: 11 nome do pai | U12: 11 NP | V12: 11 Atendim | W12: 11 Beneficio | X12: 11 email | Y12: 11 joao
A13: =A12+1 -> 12 | C13: =C12+1 -> 12 | D13: 12 nome da gestante | E13: 12 telefone | F13: 12 gest | G13: 12 parto | H13: 12 sexo | I13: 12 cpf | J13: 12 identidade | K13: 12 D Nascim | L13: 12 idad | M13: 12 trab | N13: 12 Est Civil | O13: 12 Religiao | P13: 12 Observações | Q13: 12 Endereço | R13: 12 Bairro | S13: 12 cidade | T13: 12 nome do pai | U13: 12 NP | V13: 12 Atendim | W13: 12 Beneficio | X13: 12 email | Y13: 12 joao
A14: =A13+1 -> 13 | C14: =C13+1 -> 13 | D14: 13 nome da gestante | E14: 13 telefone | F14: 13 gest | G14: 13 parto | H14: 13 sexo | I14: 13 cpf | J14: 13 identidade | K14: 13 D Nascim | L14: 13 idad | M14: 13 trab | N14: 13 Est Civil | O14: 13 Religiao | P14: 13 Observações | Q14: 13 Endereço | R14: 13 Bairro | S14: 13 cidade | T14: 13 nome do pai | U14: 13 NP | V14: 13 Atendim | W14: 13 Beneficio | X14: 13 email | Y14: 13 joao
A15: =A14+1 -> 14 | C15: =C14+1 -> 14 | D15: 14 nome da gestante | E15: 14 telefone | F15: 14 gest | G15: 14 parto | H15: 14 sexo | I15: 14 cpf | J15: 14 identidade | K15: 14 D Nascim | L15: 14 idad | M15: 14 trab | N15: 14 Est Civil | O15: 14 Religiao | P15: 14 Observações | Q15: 14 Endereço | R15: 14 Bairro | S15: 14 cidade | T15: 14 nome do pai | U15: 14 NP | V15: 14 Atendim | W15: 14 Beneficio | X15: 14 email | Y15: 14 joao
... A41: =A40+1 -> 40 | C41: =C40+1 -> 40 | D41: 40 nome da gestante | E41: 40 telefone | F41: 40 gest | G41: 40 parto | H41: 40 sexo | I41: 40 cpf | J41: 40 identidade | K41: 40 D Nascim | L41: 40 idad | M41: 40 trab | N41: 40 Est Civil | O41: 40 Religiao | P41: 40 Observações | Q41: 40 Endereço | R41: 40 Bairro | S41: 40 cidade | T41: 40 nome do pai | U41: 40 NP | V41: 40 Atendim | W41: 40 Beneficio | X41: 40 email | Y41: 40 joao
A42: =A41+1 -> 41 | B42: 1415 | C42: =C41+1 -> 41 | D42: 41 nome da gestante | E42: 41 telefone | F42: 41 gest | G42: 41 parto | H42: 41 sexo | I42: 41 cpf | J42: 41 identidade | K42: 41 D Nascim | L42: 41 idad | M42: 41 trab | N42: 41 Est Civil | O42: 41 Religiao | P42: 41 Observações | Q42: 41 Endereço | R42: 41 Bairro | S42: 41 cidade | T42: 41 nome do pai | U42: 41 NP | V42: 41 Atendim | W42: 41 Beneficio | X42: 41 email | Y42: 41 joao
A43: =A42+1 -> 42 | C43: =C42+1 -> 42 | D43: 42 nome da gestante | E43: 42 telefone | F43: 42 gest | G43: 42 parto | H43: 42 sexo | I43: 42 cpf | J43: 42 identidade | K43: 42 D Nascim | L43: 42 idad | M43: 42 trab | N43: 42 Est Civil | O43: 42 Religiao | P43: 42 Observações | Q43: 42 Endereço | R43: 42 Bairro | S43: 42 cidade | T43: 42 nome do pai | U43: 42 NP | V43: 42 Atendim | W43: 42 Beneficio | X43: 42 email | Y43: 42 joao
A44: =A43+1 -> 43 | C44: =C43+1 -> 43 | D44: 43 nome da gestante | E44: 43 telefone | F44: 43 gest | G44: 43 parto | H44: 43 sexo | I44: 43 cpf | J44: 43 identidade | K44: 43 D Nascim | L44: 43 idad | M44: 43 trab | N44: 43 Est Civil | O44: 43 Religiao | P44: 43 Observações | Q44: 43 Endereço | R44: 43 Bairro | S44: 43 cidade | T44: 43 nome do pai | U44: 43 NP | V44: 43 Atendim | W44: 43 Beneficio | X44: 43 email | Y44: 43 joao
A45: =A44+1 -> 44 | C45: =C44+1 -> 44 | D45: 44 nome da gestante | E45: 44 telefone | F45: 44 gest | G45: 44 parto | H45: 44 sexo | I45: 44 cpf | J45: 44 identidade | K45: 44 D Nascim | L45: 44 idad | M45: 44 trab | N45: 44 Est Civil | O45: 44 Religiao | P45: 44 Observações | Q45: 44 Endereço | R45: 44 Bairro | S45: 44 cidade | T45: 44 nome do pai | U45: 44 NP | V45: 44 Atendim | W45: 44 Beneficio | X45: 44 email | Y45: 44 joao
A46: =A45+1 -> 45 | C46: =C45+1 -> 45 | D46: 45 nome da gestante | E46: 45 telefone | F46: 45 gest | G46: 45 parto | H46: 45 sexo | I46: 45 cpf | J46: 45 identidade | K46: 45 D Nascim | L46: 45 idad | M46: 45 trab | N46: 45 Est Civil | O46: 45 Religiao | P46: 45 Observações | Q46: 45 Endereço | R46: 45 Bairro | S46: 45 cidade | T46: 45 nome do pai | U46: 45 NP | V46: 45 Atendim | W46: 45 Beneficio | X46: 45 email | Y46: 45 joao
A47: =A46+1 -> 46 | C47: =C46+1 -> 46 | D47: 46 nome da gestante | E47: 46 telefone | F47: 46 gest | G47: 46 parto | H47: 46 sexo | I47: 46 cpf | J47: 46 identidade | K47: 46 D Nascim | L47: 46 idad | M47: 46 trab | N47: 46 Est Civil | O47: 46 Religiao | P47: 46 Observações | Q47: 46 Endereço | R47: 46 Bairro | S47: 46 cidade | T47: 46 nome do pai | U47: 46 NP | V47: 46 Atendim | W47: 46 Beneficio | X47: 46 email | Y47: 46 joao
A48: =A47+1 -> 47 | C48: =C47+1 -> 47 | D48: 47 nome da gestante | E48: 47 telefone | F48: 47 gest | G48: 47 parto | H48: 47 sexo | I48: 47 cpf | J48: 47 identidade | K48: 47 D Nascim | L48: 47 idad | M48: 47 trab | N48: 47 Est Civil | O48: 47 Religiao | P48: 47 Observações | Q48: 47 Endereço | R48: 47 Bairro | S48: 47 cidade | T48: 47 nome do pai | U48: 47 NP | V48: 47 Atendim | W48: 47 Beneficio | X48: 47 email | Y48: 47 joao
A49: =A48+1 -> 48 | C49: =C48+1 -> 48 | D49: 48 nome da gestante | E49: 48 telefone | F49: 48 gest | G49: 48 parto | H49: 48 sexo | I49: 48 cpf | J49: 48 identidade | K49: 48 D Nascim | L49: 48 idad | M49: 48 trab | N49: 48 Est Civil | O49: 48 Religiao | P49: 48 Observações | Q49: 48 Endereço | R49: 48 Bairro | S49: 48 cidade | T49: 48 nome do pai | U49: 48 NP | V49: 48 Atendim | W49: 48 Beneficio | X49: 48 email | Y49: 48 joao
A50: =A49+1 -> 49 | C50: =C49+1 -> 49 | D50: 49 nome da gestante | E50: 49 telefone | F50: 49 gest | G50: 49 parto | H50: 49 sexo | I50: 49 cpf | J50: 49 identidade | K50: 49 D Nascim | L50: 49 idad | M50: 49 trab | N50: 49 Est Civil | O50: 49 Religiao | P50: 49 Observações | Q50: 49 Endereço | R50: 49 Bairro | S50: 49 cidade | T50: 49 nome do pai | U50: 49 NP | V50: 49 Atendim | W50: 49 Beneficio | X50: 49 email | Y50: 49 joao

Sheet LISTA DE CADASTRO
A1: Nº de Mães | B1: Carimbo de data/hora | C1: Nome Completo da Gestante | D1: Telefone com DDD e WHATSAPP | E1: Idade Gestacional | F1: Data Provável do Parto | G1: Sexo da Criança | H1: CPF da Gestante | I1: Nº da Identidade da Gestante | J1: Data de Nascimento da Gestante | K1: Idade da Gestante | L1: Está Trabalhando? | M1: Estado Civil | N1: Religião | O1: Observações | P1: Endereço Completo (Rua, Nº e Complemento) | Q1: Bairro | R1: Cidade | S1: Nome Completo do Pai da Criança | T1: Nº de Pessoas na Casa | U1: Precisa de Atendimento Profissional | V1: Recebe Benefício do Governo | W1: e-mail da Gestante | X1: Responsável pelo Cadastro
A2: 1 | B2: =IF(ISBLANK('LISTA GESTANTE DO GOOGLE FORMS'!$C2),"",('LISTA GESTANTE DO GOOGLE FORMS'!$C2)) -> 45902.369 | C2: =IF(ISBLANK('LISTA GESTANTE DO GOOGLE FORMS'!$D2),"",('LISTA GESTANTE DO GOOGLE FORMS'!$D2)) -> Stephanie Lorrayne dos Santos Freitas | D2: =IF(ISBLANK('LISTA GESTANTE DO GOOGLE FORMS'!$E2),"",('LISTA GESTANTE DO GOOGLE FORMS'!$E2)) -> (31) 99282-4775 | E2: =IF(ISBLANK('LISTA GESTANTE DO GOOGLE FORMS'!$F2),"",('LISTA GESTANTE DO GOOGLE FORMS'!$F2)) -> 7º Mês | F2: =IF(ISBLANK('LISTA GESTANTE DO GOOGLE FORMS'!$G2),"",('LISTA GESTANTE DO GOOGLE FORMS'!$G2)) -> 45969 | G2: =IF(ISBLANK('LISTA GESTANTE DO GOOGLE FORMS'!$H2),"",('LISTA GESTANTE DO GOOGLE FORMS'!$H2)) -> Menina | H2: =IF(ISBLANK('LISTA GESTANTE DO GOOGLE FORMS'!$I2),"",('LISTA GESTANTE DO GOOGLE FORMS'!$I2)) -> 124.527.806-18 | I2: =IF(ISBLANK('LISTA GESTANTE DO GOOGLE FORMS'!$J2),"",('LISTA GESTANTE DO GOOGLE FORMS'!$J2)) -> MG 23.145.828 | J2: =IF(ISBLANK('LISTA GESTANTE DO GOOGLE FORMS'!$K2),"",('LISTA GESTANTE DO GOOGLE FORMS'!$K2)) -> 36883 | K2: =IF(ISBLANK('LISTA GESTANTE DO GOOGLE FORMS'!$L2),"",('LISTA GESTANTE DO GOOGLE FORMS'!$L2)) -> 25 | L2: =IF(ISBLANK('LISTA GESTANTE DO GOOGLE FORMS'!$M2),"",('LISTA GESTANTE DO GOOGLE FORMS'!$M2)) -> Não | M2: =IF(ISBLANK('LISTA GESTANTE DO GOOGLE FORMS'!$N2),"",('LISTA GESTANTE DO GOOGLE FORMS'!$N2)) -> União Estável | N2: =IF(ISBLANK('LISTA GESTANTE DO GOOGLE FORMS'!$O2),"",('LISTA GESTANTE DO GOOGLE FORMS'!$O2)) -> Evangélica | O2: =IF(ISBLANK('LISTA GESTANTE DO GOOGLE FORMS'!$P2),"",('LISTA GESTANTE DO GOOGLE FORMS'!$P2)) -> Gestante Antecipada para Outubro para compor o evento | P2: =IF(ISBLANK('LISTA GESTANTE DO GOOGLE FORMS'!$Q2),"",('LISTA GESTANTE DO GOOGLE FORMS'!$Q2)) -> Avenida Jeferson Coelho da Silva, 369 - Bloco 2 Apt 401 | Q2: =IF(ISBLANK('LISTA GESTANTE DO GOOGLE FORMS'!$R2),"",('LISTA GESTANTE DO GOOGLE FORMS'!$R2)) -> Parque Estrela do Sul | R2: =IF(ISBLANK('LISTA GESTANTE DO GOOGLE FORMS'!$S2),"",('LISTA GESTANTE DO GOOGLE FORMS'!$S2)) -> Ribeirão das Neves | S2: =IF(ISBLANK('LISTA GESTANTE DO GOOGLE FORMS'!$T2),"",('LISTA GESTANTE DO GOOGLE FORMS'!$T2)) -> Stephanie Lorrayne dos Santos Freitas | T2: =IF(ISBLANK('LISTA GESTANTE DO GOOGLE FORMS'!$U2),"",('LISTA GESTANTE DO GOOGLE FORMS'!$U2)) -> 1 NP | U2: =IF(ISBLANK('LISTA GESTANTE DO GOOGLE FORMS'!$V2),"",('LISTA GESTANTE DO GOOGLE FORMS'!$V2)) -> Psicólogo | V2: =IF(ISBLANK('LISTA GESTANTE DO GOOGLE FORMS'!$W2),"",('LISTA GESTANTE DO GOOGLE FORMS'!$W2)) -> Bolsa Família | W2: =IF(ISBLANK('LISTA GESTANTE DO GOOGLE FORMS'!$X2),"",('LISTA GESTANTE DO GOOGLE FORMS'!$X2)) -> josecarlos1990@gmail.com | X2: =IF(ISBLANK('LISTA GESTANTE DO GOOGLE FORMS'!$Y2),"",('LISTA GESTANTE DO GOOGLE FORMS'!$Y2)) -> João
A3: =A2+1 -> 2 | B3: =IF(ISBLANK('LISTA GESTANTE DO GOOGLE FORMS'!$C3),"",('LISTA GESTANTE DO GOOGLE FORMS'!$C3)) -> 2 | C3: =IF(ISBLANK('LISTA GESTANTE DO GOOGLE FORMS'!$D3),"",('LISTA GESTANTE DO GOOGLE FORMS'!$D3)) -> 2 nome da gestante | D3: =IF(ISBLANK('LISTA GESTANTE DO GOOGLE FORMS'!$E3),"",('LISTA GESTANTE DO GOOGLE FORMS'!$E3)) -> 2 telefone | E3: =IF(ISBLANK('LISTA GESTANTE DO GOOGLE FORMS'!$F3),"",('LISTA GESTANTE DO GOOGLE FORMS'!$F3)) -> 2 gest | F3: =IF(ISBLANK('LISTA GESTANTE DO GOOGLE FORMS'!$G3),"",('LISTA GESTANTE DO GOOGLE FORMS'!$G3)) -> 2 parto | G3: =IF(ISBLANK('LISTA GESTANTE DO GOOGLE FORMS'!$H3),"",('LISTA GESTANTE DO GOOGLE FORMS'!$H3)) -> 2 sexo | H3: =IF(ISBLANK('LISTA GESTANTE DO GOOGLE FORMS'!$I3),"",('LISTA GESTANTE DO GOOGLE FORMS'!$I3)) -> 2 cpf | I3: =IF(ISBLANK('LISTA GESTANTE DO GOOGLE FORMS'!$J3),"",('LISTA GESTANTE DO GOOGLE FORMS'!$J3)) -> 2 identidade | J3: =IF(ISBLANK('LISTA GESTANTE DO GOOGLE FORMS'!$K3),"",('LISTA GESTANTE DO GOOGLE FORMS'!$K3)) -> 2 D Nascim | K3: =IF(ISBLANK('LISTA GESTANTE DO GOOGLE FORMS'!$L3),"",('LISTA GESTANTE DO GOOGLE FORMS'!$L3)) -> 2 idad | L3: =IF(ISBLANK('LISTA GESTANTE DO GOOGLE FORMS'!$M3),"",('LISTA GESTANTE DO GOOGLE FORMS'!$M3)) -> 2 trab | M3: =IF(ISBLANK('LISTA GESTANTE DO GOOGLE FORMS'!$N3),"",('LISTA GESTANTE DO GOOGLE FORMS'!$N3)) -> 2 Est Civil | N3: =IF(ISBLANK('LISTA GESTANTE DO GOOGLE FORMS'!$O3),"",('LISTA GESTANTE DO GOOGLE FORMS'!$O3)) -> 2 Religiao | O3: =IF(ISBLANK('LISTA GESTANTE DO GOOGLE FORMS'!$P3),"",('LISTA GESTANTE DO GOOGLE FORMS'!$P3)) -> 2 Observações | P3: =IF(ISBLANK('LISTA GESTANTE DO GOOGLE FORMS'!$Q3),"",('LISTA GESTANTE DO GOOGLE FORMS'!$Q3)) -> 2 Endereço | Q3: =IF(ISBLANK('LISTA GESTANTE DO GOOGLE FORMS'!$R3),"",('LISTA GESTANTE DO GOOGLE FORMS'!$R3)) -> 2 Bairro | R3: =IF(ISBLANK('LISTA GESTANTE DO GOOGLE FORMS'!$S3),"",('LISTA GESTANTE DO GOOGLE FORMS'!$S3)) -> 2 cidade | S3: =IF(ISBLANK('LISTA GESTANTE DO GOOGLE FORMS'!$T3),"",('LISTA GESTANTE DO GOOGLE FORMS'!$T3)) -> 2 nome do pai | T3: =IF(ISBLANK('LISTA GESTANTE DO GOOGLE FORMS'!$U3),"",('LISTA GESTANTE DO GOOGLE FORMS'!$U3)) -> 2 NP | U3: =IF(ISBLANK('LISTA GESTANTE DO GOOGLE FORMS'!$V3),"",('LISTA GESTANTE DO GOOGLE FORMS'!$V3)) -> 2 Atendim | V3: =IF(ISBLANK('LISTA GESTANTE DO GOOGLE FORMS'!$W3),"",('LISTA GESTANTE DO GOOGLE FORMS'!$W3)) -> 2 Beneficio | W3: =IF(ISBLANK('LISTA GESTANTE DO GOOGLE FORMS'!$X3),"",('LISTA GESTANTE DO GOOGLE FORMS'!$X3)) -> 2 email | X3: =IF(ISBLANK('LISTA GESTANTE DO GOOGLE FORMS'!$Y3),"",('LISTA GESTANTE DO GOOGLE FORMS'!$Y3)) -> 2 joao
A4: =A3+1 -> 3 | B4: =IF(ISBLANK('LISTA GESTANTE DO GOOGLE FORMS'!$C4),"",('LISTA GESTANTE DO GOOGLE FORMS'!$C4)) -> 3 | C4: =IF(ISBLANK('LISTA GESTANTE DO GOOGLE FORMS'!$D4),"",('LISTA GESTANTE DO GOOGLE FORMS'!$D4)) -> 3 nome da gestante | D4: =IF(ISBLANK('LISTA GESTANTE DO GOOGLE FORMS'!$E4),"",('LISTA GESTANTE DO GOOGLE FORMS'!$E4)) -> 3 telefone | E4: =IF(ISBLANK('LISTA GESTANTE DO GOOGLE FORMS'!$F4),"",('LISTA GESTANTE DO GOOGLE FORMS'!$F4)) -> 3 gest | F4: =IF(ISBLANK('LISTA GESTANTE DO GOOGLE FORMS'!$G4),"",('LISTA GESTANTE DO GOOGLE FORMS'!$G4)) -> 3 parto | G4: =IF(ISBLANK('LISTA GESTANTE DO GOOGLE FORMS'!$H4),"",('LISTA GESTANTE DO GOOGLE FORMS'!$H4)) -> 3 sexo | H4: =IF(ISBLANK('LISTA GESTANTE DO GOOGLE FORMS'!$I4),"",('LISTA GESTANTE DO GOOGLE FORMS'!$I4)) -> 3 cpf | I4: =IF(ISBLANK('LISTA GESTANTE DO GOOGLE FORMS'!$J4),"",('LISTA GESTANTE DO GOOGLE FORMS'!$J4)) -> 3 identidade | J4: =IF(ISBLANK('LISTA GESTANTE DO GOOGLE FORMS'!$K4),"",('LISTA GESTANTE DO GOOGLE FORMS'!$K4)) -> 3 D Nascim | K4: =IF(ISBLANK('LISTA GESTANTE DO GOOGLE FORMS'!$L4),"",('LISTA GESTANTE DO GOOGLE FORMS'!$L4)) -> 3 idad | L4: =IF(ISBLANK('LISTA GESTANTE DO GOOGLE FORMS'!$M4),"",('LISTA GESTANTE DO GOOGLE FORMS'!$M4)) -> 3 trab | M4: =IF(ISBLANK('LISTA GESTANTE DO GOOGLE FORMS'!$N4),"",('LISTA GESTANTE DO GOOGLE FORMS'!$N4)) -> 3 Est Civil | N4: =IF(ISBLANK('LISTA GESTANTE DO GOOGLE FORMS'!$O4),"",('LISTA GESTANTE DO GOOGLE FORMS'!$O4)) -> 3 Religiao | O4: =IF(ISBLANK('LISTA GESTANTE DO GOOGLE FORMS'!$P4),"",('LISTA GESTANTE DO GOOGLE FORMS'!$P4)) -> 3 Observações | P4: =IF(ISBLANK('LISTA GESTANTE DO GOOGLE FORMS'!$Q4),"",('LISTA GESTANTE DO GOOGLE FORMS'!$Q4)) -> 3 Endereço | Q4: =IF(ISBLANK('LISTA GESTANTE DO GOOGLE FORMS'!$R4),"",('LISTA GESTANTE DO GOOGLE FORMS'!$R4)) -> 3 Bairro | R4: =IF(ISBLANK('LISTA GESTANTE DO GOOGLE FORMS'!$S4),"",('LISTA GESTANTE DO GOOGLE FORMS'!$S4)) -> 3 cidade | S4: =IF(ISBLANK('LISTA GESTANTE DO GOOGLE FORMS'!$T4),"",('LISTA GESTANTE DO GOOGLE FORMS'!$T4)) -> 3 nome do pai | T4: =IF(ISBLANK('LISTA GESTANTE DO GOOGLE FORMS'!$U4),"",('LISTA GESTANTE DO GOOGLE FORMS'!$U4)) -> 3 NP | U4: =IF(ISBLANK('LISTA GESTANTE DO GOOGLE FORMS'!$V4),"",('LISTA GESTANTE DO GOOGLE FORMS'!$V4)) -> 3 Atendim | V4: =IF(ISBLANK('LISTA GESTANTE DO GOOGLE FORMS'!$W4),"",('LISTA GESTANTE DO GOOGLE FORMS'!$W4)) -> 3 Beneficio | W4: =IF(ISBLANK('LISTA GESTANTE DO GOOGLE FORMS'!$X4),"",('LISTA GESTANTE DO GOOGLE FORMS'!$X4)) -> 3 email | X4: =IF(ISBLANK('LISTA GESTANTE DO GOOGLE FORMS'!$Y4),"",('LISTA GESTANTE DO GOOGLE FORMS'!$Y4)) -> 3 joao
A5: =A4+1 -> 4 | B5: =IF(ISBLANK('LISTA GESTANTE DO GOOGLE FORMS'!$C5),"",('LISTA GESTANTE DO GOOGLE FORMS'!$C5)) -> 4 | C5: =IF(ISBLANK('LISTA GESTANTE DO GOOGLE FORMS'!$D5),"",('LISTA GESTANTE DO GOOGLE FORMS'!$D5)) -> 4 nome da gestante | D5: =IF(ISBLANK('LISTA GESTANTE DO GOOGLE FORMS'!$E5),"",('LISTA GESTANTE DO GOOGLE FORMS'!$E5)) -> 4 telefone | E5: =IF(ISBLANK('LISTA GESTANTE DO GOOGLE FORMS'!$F5),"",('LISTA GESTANTE DO GOOGLE FORMS'!$F5)) -> 4 gest | F5: =IF(ISBLANK('LISTA GESTANTE DO GOOGLE FORMS'!$G5),"",('LISTA GESTANTE DO GOOGLE FORMS'!$G5)) -> 4 parto | G5: =IF(ISBLANK('LISTA GESTANTE DO GOOGLE FORMS'!$H5),"",('LISTA GESTANTE DO GOOGLE FORMS'!$H5)) -> 4 sexo | H5: =IF(ISBLANK('LISTA GESTANTE DO GOOGLE FORMS'!$I5),"",('LISTA GESTANTE DO GOOGLE FORMS'!$I5)) -> 4 cpf | I5: =IF(ISBLANK('LISTA GESTANTE DO GOOGLE FORMS'!$J5),"",('LISTA GESTANTE DO GOOGLE FORMS'!$J5)) -> 4 identidade | J5: =IF(ISBLANK('LISTA GESTANTE DO GOOGLE FORMS'!$K5),"",('LISTA GESTANTE DO GOOGLE FORMS'!$K5)) -> 4 D Nascim | K5: =IF(ISBLANK('LISTA GESTANTE DO GOOGLE FORMS'!$L5),"",('LISTA GESTANTE DO GOOGLE FORMS'!$L5)) -> 4 idad | L5: =IF(ISBLANK('LISTA GESTANTE DO GOOGLE FORMS'!$M5),"",('LISTA GESTANTE DO GOOGLE FORMS'!$M5)) -> 4 trab | M5: =IF(ISBLANK('LISTA GESTANTE DO GOOGLE FORMS'!$N5),"",('LISTA GESTANTE DO GOOGLE FORMS'!$N5)) -> 4 Est Civil | N5: =IF(ISBLANK('LISTA GESTANTE DO GOOGLE FORMS'!$O5),"",('LISTA GESTANTE DO GOOGLE FORMS'!$O5)) -> 4 Religiao | O5: =IF(ISBLANK('LISTA GESTANTE DO GOOGLE FORMS'!$P5),"",('LISTA GESTANTE DO GOOGLE FORMS'!$P5)) -> 4 Observações | P5: =IF(ISBLANK('LISTA GESTANTE DO GOOGLE FORMS'!$Q5),"",('LISTA GESTANTE DO GOOGLE FORMS'!$Q5)) -> 4 Endereço | Q5: =IF(ISBLANK('LISTA GESTANTE DO GOOGLE FORMS'!$R5),"",('LISTA GESTANTE DO GOOGLE FORMS'!$R5)) -> 4 Bairro | R5: =IF(ISBLANK('LISTA GESTANTE DO GOOGLE FORMS'!$S5),"",('LISTA GESTANTE DO GOOGLE FORMS'!$S5)) -> 4 cidade | S5: =IF(ISBLANK('LISTA GESTANTE DO GOOGLE FORMS'!$T5),"",('LISTA GESTANTE DO GOOGLE FORMS'!$T5)) -> 4 nome do pai | T5: =IF(ISBLANK('LISTA GESTANTE DO GOOGLE FORMS'!$U5),"",('LISTA GESTANTE DO GOOGLE FORMS'!$U5)) -> 4 NP | U5: =IF(ISBLANK('LISTA GESTANTE DO GOOGLE FORMS'!$V5),"",('LISTA GESTANTE DO GOOGLE FORMS'!$V5)) -> 4 Atendim | V5: =IF(ISBLANK('LISTA GESTANTE DO GOOGLE FORMS'!$W5),"",('LISTA GESTANTE DO GOOGLE FORMS'!$W5)) -> 4 Beneficio | W5: =IF(ISBLANK('LISTA GESTANTE DO GOOGLE FORMS'!$X5),"",('LISTA GESTANTE DO GOOGLE FORMS'!$X5)) -> 4 email | X5: =IF(ISBLANK('LISTA GESTANTE DO GOOGLE FORMS'!$Y5),"",('LISTA GESTANTE DO GOOGLE FORMS'!$Y5)) -> 4 joao
A6: =A5+1 -> 5 | B6: =IF(ISBLANK('LISTA GESTANTE DO GOOGLE FORMS'!$C6),"",('LISTA GESTANTE DO GOOGLE FORMS'!$C6)) -> 5 | C6: =IF(ISBLANK('LISTA GESTANTE DO GOOGLE FORMS'!$D6),"",('LISTA GESTANTE DO GOOGLE FORMS'!$D6)) -> 5 nome da gestante | D6: =IF(ISBLANK('LISTA GESTANTE DO GOOGLE FORMS'!$E6),"",('LISTA GESTANTE DO GOOGLE FORMS'!$E6)) -> 5 telefone | E6: =IF(ISBLANK('LISTA GESTANTE DO GOOGLE FORMS'!$F6),"",('LISTA GESTANTE DO GOOGLE FORMS'!$F6)) -> 5 gest | F6: =IF(ISBLANK('LISTA GESTANTE DO GOOGLE FORMS'!$G6),"",('LISTA GESTANTE DO GOOGLE FORMS'!$G6)) -> 5 parto | G6: =IF(ISBLANK('LISTA GESTANTE DO GOOGLE FORMS'!$H6),"",('LISTA GESTANTE DO GOOGLE FORMS'!$H6)) -> 5 sexo | H6: =IF(ISBLANK('LISTA GESTANTE DO GOOGLE FORMS'!$I6),"",('LISTA GESTANTE DO GOOGLE FORMS'!$I6)) -> 5 cpf | I6: =IF(ISBLANK('LISTA GESTANTE DO GOOGLE FORMS'!$J6),"",('LISTA GESTANTE DO GOOGLE FORMS'!$J6)) -> 5 identidade | J6: =IF(ISBLANK('LISTA GESTANTE DO GOOGLE FORMS'!$K6),"",('LISTA GESTANTE DO GOOGLE FORMS'!$K6)) -> 5 D Nascim | K6: =IF(ISBLANK('LISTA GESTANTE DO GOOGLE FORMS'!$L6),"",('LISTA GESTANTE DO GOOGLE FORMS'!$L6)) -> 5 idad | L6: =IF(ISBLANK('LISTA GESTANTE DO GOOGLE FORMS'!$M6),"",('LISTA GESTANTE DO GOOGLE FORMS'!$M6)) -> 5 trab | M6: =IF(ISBLANK('LISTA GESTANTE DO GOOGLE FORMS'!$N6),"",('LISTA GESTANTE DO GOOGLE FORMS'!$N6)) -> 5 Est Civil | N6: =IF(ISBLANK('LISTA GESTANTE DO GOOGLE FORMS'!$O6),"",('LISTA GESTANTE DO GOOGLE FORMS'!$O6)) -> 5 Religiao | O6: =IF(ISBLANK('LISTA GESTANTE DO GOOGLE FORMS'!$P6),"",('LISTA GESTANTE DO GOOGLE FORMS'!$P6)) -> 5 Observações | P6: =IF(ISBLANK('LISTA GESTANTE DO GOOGLE FORMS'!$Q6),"",('LISTA GESTANTE DO GOOGLE FORMS'!$Q6)) -> 5 Endereço | Q6: =IF(ISBLANK('LISTA GESTANTE DO GOOGLE FORMS'!$R6),"",('LISTA GESTANTE DO GOOGLE FORMS'!$R6)) -> 5 Bairro | R6: =IF(ISBLANK('LISTA GESTANTE DO GOOGLE FORMS'!$S6),"",('LISTA GESTANTE DO GOOGLE FORMS'!$S6)) -> 5 cidade | S6: =IF(ISBLANK('LISTA GESTANTE DO GOOGLE FORMS'!$T6),"",('LISTA GESTANTE DO GOOGLE FORMS'!$T6)) -> 5 nome do pai | T6: =IF(ISBLANK('LISTA GESTANTE DO GOOGLE FORMS'!$U6),"",('LISTA GESTANTE DO GOOGLE FORMS'!$U6)) -> 5 NP | U6: =IF(ISBLANK('LISTA GESTANTE DO GOOGLE FORMS'!$V6),"",('LISTA GESTANTE DO GOOGLE FORMS'!$V6)) -> 5 Atendim | V6: =IF(ISBLANK('LISTA GESTANTE DO GOOGLE FORMS'!$W6),"",('LISTA GESTANTE DO GOOGLE FORMS'!$W6)) -> 5 Beneficio | W6: =IF(ISBLANK('LISTA GESTANTE DO GOOGLE FORMS'!$X6),"",('LISTA GESTANTE DO GOOGLE FORMS'!$X6)) -> 5 email | X6: =IF(ISBLANK('LISTA GESTANTE DO GOOGLE FORMS'!$Y6),"",('LISTA GESTANTE DO GOOGLE FORMS'!$Y6)) -> 5 joao
A7: =A6+1 -> 6 | B7: =IF(ISBLANK('LISTA GESTANTE DO GOOGLE FORMS'!$C7),"",('LISTA GESTANTE DO GOOGLE FORMS'!$C7)) -> 6 | C7: =IF(ISBLANK('LISTA GESTANTE DO GOOGLE FORMS'!$D7),"",('LISTA GESTANTE DO GOOGLE FORMS'!$D7)) -> 6 nome da gestante | D7: =IF(ISBLANK('LISTA GESTANTE DO GOOGLE FORMS'!$E7),"",('LISTA GESTANTE DO GOOGLE FORMS'!$E7)) -> 6 telefone | E7: =IF(ISBLANK('LISTA GESTANTE DO GOOGLE FORMS'!$F7),"",('LISTA GESTANTE DO GOOGLE FORMS'!$F7)) -> 6 gest | F7: =IF(ISBLANK('LISTA GESTANTE DO GOOGLE FORMS'!$G7),"",('LISTA GESTANTE DO GOOGLE FORMS'!$G7)) -> 6 parto | G7: =IF(ISBLANK('LISTA GESTANTE DO GOOGLE FORMS'!$H7),"",('LISTA GESTANTE DO GOOGLE FORMS'!$H7)) -> 6 sexo | H7: =IF(ISBLANK('LISTA GESTANTE DO GOOGLE FORMS'!$I7),"",('LISTA GESTANTE DO GOOGLE FORMS'!$I7)) -> 6 cpf | I7: =IF(ISBLANK('LISTA GESTANTE DO GOOGLE FORMS'!$J7),"",('LISTA GESTANTE DO GOOGLE FORMS'!$J7)) -> 6 identidade | J7: =IF(ISBLANK('LISTA GESTANTE DO GOOGLE FORMS'!$K7),"",('LISTA GESTANTE DO GOOGLE FORMS'!$K7)) -> 6 D Nascim | K7: =IF(ISBLANK('LISTA GESTANTE DO GOOGLE FORMS'!$L7),"",('LISTA GESTANTE DO GOOGLE FORMS'!$L7)) -> 6 idad | L7: =IF(ISBLANK('LISTA GESTANTE DO GOOGLE FORMS'!$M7),"",('LISTA GESTANTE DO GOOGLE FORMS'!$M7)) -> 6 trab | M7: =IF(ISBLANK('LISTA GESTANTE DO GOOGLE FORMS'!$N7),"",('LISTA GESTANTE DO GOOGLE FORMS'!$N7)) -> 6 Est Civil | N7: =IF(ISBLANK('LISTA GESTANTE DO GOOGLE FORMS'!$O7),"",('LISTA GESTANTE DO GOOGLE FORMS'!$O7)) -> 6 Religiao | O7: =IF(ISBLANK('LISTA GESTANTE DO GOOGLE FORMS'!$P7),"",('LISTA GESTANTE DO GOOGLE FORMS'!$P7)) -> 6 Observações | P7: =IF(ISBLANK('LISTA GESTANTE DO GOOGLE FORMS'!$Q7),"",('LISTA GESTANTE DO GOOGLE FORMS'!$Q7)) -> 6 Endereço | Q7: =IF(ISBLANK('LISTA GESTANTE DO GOOGLE FORMS'!$R7),"",('LISTA GESTANTE DO GOOGLE FORMS'!$R7)) -> 6 Bairro | R7: =IF(ISBLANK('LISTA GESTANTE DO GOOGLE FORMS'!$S7),"",('LISTA GESTANTE DO GOOGLE FORMS'!$S7)) -> 6 cidade | S7: =IF(ISBLANK('LISTA GESTANTE DO GOOGLE FORMS'!$T7),"",('LISTA GESTANTE DO GOOGLE FORMS'!$T7)) -> 6 nome do pai | T7: =IF(ISBLANK('LISTA GESTANTE DO GOOGLE FORMS'!$U7),"",('LISTA GESTANTE DO GOOGLE FORMS'!$U7)) -> 6 NP | U7: =IF(ISBLANK('LISTA GESTANTE DO GOOGLE FORMS'!$V7),"",('LISTA GESTANTE DO GOOGLE FORMS'!$V7)) -> 6 Atendim | V7: =IF(ISBLANK('LISTA GESTANTE DO GOOGLE FORMS'!$W7),"",('LISTA GESTANTE DO GOOGLE FORMS'!$W7)) -> 6 Beneficio | W7: =IF(ISBLANK('LISTA GESTANTE DO GOOGLE FORMS'!$X7),"",('LISTA GESTANTE DO GOOGLE FORMS'!$X7)) -> 6 email | X7: =IF(ISBLANK('LISTA GESTANTE DO GOOGLE FORMS'!$Y7),"",('LISTA GESTANTE DO GOOGLE FORMS'!$Y7)) -> 6 joao
A8: =A7+1 -> 7 | B8: =IF(ISBLANK('LISTA GESTANTE DO GOOGLE FORMS'!$C8),"",('LISTA GESTANTE DO GOOGLE FORMS'!$C8)) -> 7 | C8: =IF(ISBLANK('LISTA GESTANTE DO GOOGLE FORMS'!$D8),"",('LISTA GESTANTE DO GOOGLE FORMS'!$D8)) -> 7 nome da gestante | D8: =IF(ISBLANK('LISTA GESTANTE DO GOOGLE FORMS'!$E8),"",('LISTA GESTANTE DO GOOGLE FORMS'!$E8)) -> 7 telefone | E8: =IF(ISBLANK('LISTA GESTANTE DO GOOGLE FORMS'!$F8),"",('LISTA GESTANTE DO GOOGLE FORMS'!$F8)) -> 7 gest | F8: =IF(ISBLANK('LISTA GESTANTE DO GOOGLE FORMS'!$G8),"",('LISTA GESTANTE DO GOOGLE FORMS'!$G8)) -> 7 parto | G8: =IF(ISBLANK('LISTA GESTANTE DO GOOGLE FORMS'!$H8),"",('LISTA GESTANTE DO GOOGLE FORMS'!$H8)) -> 7 sexo | H8: =IF(ISBLANK('LISTA GESTANTE DO GOOGLE FORMS'!$I8),"",('LISTA GESTANTE DO GOOGLE FORMS'!$I8)) -> 7 cpf | I8: =IF(ISBLANK('LISTA GESTANTE DO GOOGLE FORMS'!$J8),"",('LISTA GESTANTE DO GOOGLE FORMS'!$J8)) -> 7 identidade | J8: =IF(ISBLANK('LISTA GESTANTE DO GOOGLE FORMS'!$K8),"",('LISTA GESTANTE DO GOOGLE FORMS'!$K8)) -> 7 D Nascim | K8: =IF(ISBLANK('LISTA GESTANTE DO GOOGLE FORMS'!$L8),"",('LISTA GESTANTE DO GOOGLE FORMS'!$L8)) -> 7 idad | L8: =IF(ISBLANK('LISTA GESTANTE DO GOOGLE FORMS'!$M8),"",('LISTA GESTANTE DO GOOGLE FORMS'!$M8)) -> 7 trab | M8: =IF(ISBLANK('LISTA GESTANTE DO GOOGLE FORMS'!$N8),"",('LISTA GESTANTE DO GOOGLE FORMS'!$N8)) -> 7 Est Civil | N8: =IF(ISBLANK('LISTA GESTANTE DO GOOGLE FORMS'!$O8),"",('LISTA GESTANTE DO GOOGLE FORMS'!$O8)) -> 7 Religiao | O8: =IF(ISBLANK('LISTA GESTANTE DO GOOGLE FORMS'!$P8),"",('LISTA GESTANTE DO GOOGLE FORMS'!$P8)) -> 7 Observações | P8: =IF(ISBLANK('LISTA GESTANTE DO GOOGLE FORMS'!$Q8),"",('LISTA GESTANTE DO GOOGLE FORMS'!$Q8)) -> 7 Endereço | Q8: =IF(ISBLANK('LISTA GESTANTE DO GOOGLE FORMS'!$R8),"",('LISTA GESTANTE DO GOOGLE FORMS'!$R8)) -> 7 Bairro | R8: =IF(ISBLANK('LISTA GESTANTE DO GOOGLE FORMS'!$S8),"",('LISTA GESTANTE DO GOOGLE FORMS'!$S8)) -> 7 cidade | S8: =IF(ISBLANK('LISTA GESTANTE DO GOOGLE FORMS'!$T8),"",('LISTA GESTANTE DO GOOGLE FORMS'!$T8)) -> 7 nome do pai | T8: =IF(ISBLANK('LISTA GESTANTE DO GOOGLE FORMS'!$U8),"",('LISTA GESTANTE DO GOOGLE FORMS'!$U8)) -> 7 NP | U8: =IF(ISBLANK('LISTA GESTANTE DO GOOGLE FORMS'!$V8),"",('LISTA GESTANTE DO GOOGLE FORMS'!$V8)) -> 7 Atendim | V8: =IF(ISBLANK('LISTA GESTANTE DO GOOGLE FORMS'!$W8),"",('LISTA GESTANTE DO GOOGLE FORMS'!$W8)) -> 7 Beneficio | W8: =IF(ISBLANK('LISTA GESTANTE DO GOOGLE FORMS'!$X8),"",('LISTA GESTANTE DO GOOGLE FORMS'!$X8)) -> 7 email | X8: =IF(ISBLANK('LISTA GESTANTE DO GOOGLE FORMS'!$Y8),"",('LISTA GESTANTE DO GOOGLE FORMS'!$Y8)) -> 7 joao
A9: =A8+1 -> 8 | B9: =IF(ISBLANK('LISTA GESTANTE DO GOOGLE FORMS'!$C9),"",('LISTA GESTANTE DO GOOGLE FORMS'!$C9)) -> 8 | C9: =IF(ISBLANK('LISTA GESTANTE DO GOOGLE FORMS'!$D9),"",('LISTA GESTANTE DO GOOGLE FORMS'!$D9)) -> 8 nome da gestante | D9: =IF(ISBLANK('LISTA GESTANTE DO GOOGLE FORMS'!$E9),"",('LISTA GESTANTE DO GOOGLE FORMS'!$E9)) -> 8 telefone | E9: =IF(ISBLANK('LISTA GESTANTE DO GOOGLE FORMS'!$F9),"",('LISTA GESTANTE DO GOOGLE FORMS'!$F9)) -> 8 gest | F9: =IF(ISBLANK('LISTA GESTANTE DO GOOGLE FORMS'!$G9),"",('LISTA GESTANTE DO GOOGLE FORMS'!$G9)) -> 8 parto | G9: =IF(ISBLANK('LISTA GESTANTE DO GOOGLE FORMS'!$H9),"",('LISTA GESTANTE DO GOOGLE FORMS'!$H9)) -> 8 sexo | H9: =IF(ISBLANK('LISTA GESTANTE DO GOOGLE FORMS'!$I9),"",('LISTA GESTANTE DO GOOGLE FORMS'!$I9)) -> 8 cpf | I9: =IF(ISBLANK('LISTA GESTANTE DO GOOGLE FORMS'!$J9),"",('LISTA GESTANTE DO GOOGLE FORMS'!$J9)) -> 8 identidade | J9: =IF(ISBLANK('LISTA GESTANTE DO GOOGLE FORMS'!$K9),"",('LISTA GESTANTE DO GOOGLE FORMS'!$K9)) -> 8 D Nascim | K9: =IF(ISBLANK('LISTA GESTANTE DO GOOGLE FORMS'!$L9),"",('LISTA GESTANTE DO GOOGLE FORMS'!$L9)) -> 8 idad | L9: =IF(ISBLANK('LISTA GESTANTE DO GOOGLE FORMS'!$M9),"",('LISTA GESTANTE DO GOOGLE FORMS'!$M9)) -> 8 trab | M9: =IF(ISBLANK('LISTA GESTANTE DO GOOGLE FORMS'!$N9),"",('LISTA GESTANTE DO GOOGLE FORMS'!$N9)) -> 8 Est Civil | N9: =IF(ISBLANK('LISTA GESTANTE DO GOOGLE FORMS'!$O9),"",('LISTA GESTANTE DO GOOGLE FORMS'!$O9)) -> 8 Religiao | O9: =IF(ISBLANK('LISTA GESTANTE DO GOOGLE FORMS'!$P9),"",('LISTA GESTANTE DO GOOGLE FORMS'!$P9)) -> 8 Observações | P9: =IF(ISBLANK('LISTA GESTANTE DO GOOGLE FORMS'!$Q9),"",('LISTA GESTANTE DO GOOGLE FORMS'!$Q9)) -> 8 Endereço | Q9: =IF(ISBLANK('LISTA GESTANTE DO GOOGLE FORMS'!$R9),"",('LISTA GESTANTE DO GOOGLE FORMS'!$R9)) -> 8 Bairro | R9: =IF(ISBLANK('LISTA GESTANTE DO GOOGLE FORMS'!$S9),"",('LISTA GESTANTE DO GOOGLE FORMS'!$S9)) -> 8 cidade | S9: =IF(ISBLANK('LISTA GESTANTE DO GOOGLE FORMS'!$T9),"",('LISTA GESTANTE DO GOOGLE FORMS'!$T9)) -> 8 nome do pai | T9: =IF(ISBLANK('LISTA GESTANTE DO GOOGLE FORMS'!$U9),"",('LISTA GESTANTE DO GOOGLE FORMS'!$U9)) -> 8 NP | U9: =IF(ISBLANK('LISTA GESTANTE DO GOOGLE FORMS'!$V9),"",('LISTA GESTANTE DO GOOGLE FORMS'!$V9)) -> 8 Atendim | V9: =IF(ISBLANK('LISTA GESTANTE DO GOOGLE FORMS'!$W9),"",('LISTA GESTANTE DO GOOGLE FORMS'!$W9)) -> 8 Beneficio | W9: =IF(ISBLANK('LISTA GESTANTE DO GOOGLE FORMS'!$X9),"",('LISTA GESTANTE DO GOOGLE FORMS'!$X9)) -> 8 email | X9: =IF(ISBLANK('LISTA GESTANTE DO GOOGLE FORMS'!$Y9),"",('LISTA GESTANTE DO GOOGLE FORMS'!$Y9)) -> 8 joao
A10: =A9+1 -> 9 | B10: =IF(ISBLANK('LISTA GESTANTE DO GOOGLE FORMS'!$C10),"",('LISTA GESTANTE DO GOOGLE FORMS'!$C10)) -> 9 | C10: =IF(ISBLANK('LISTA GESTANTE DO GOOGLE FORMS'!$D10),"",('LISTA GESTANTE DO GOOGLE FORMS'!$D10)) -> 9 nome da gestante | D10: =IF(ISBLANK('LISTA GESTANTE DO GOOGLE FORMS'!$E10),"",('LISTA GESTANTE DO GOOGLE FORMS'!$E10)) -> 9 telefone | E10: =IF(ISBLANK('LISTA GESTANTE DO GOOGLE FORMS'!$F10),"",('LISTA GESTANTE DO GOOGLE FORMS'!$F10)) -> 9 gest | F10: =IF(ISBLANK('LISTA GESTANTE DO GOOGLE FORMS'!$G10),"",('LISTA GESTANTE DO GOOGLE FORMS'!$G10)) -> 9 parto | G10: =IF(ISBLANK('LISTA GESTANTE DO GOOGLE FORMS'!$H10),"",('LISTA GESTANTE DO GOOGLE FORMS'!$H10)) -> 9 sexo | H10: =IF(ISBLANK('LISTA GESTANTE DO GOOGLE FORMS'!$I10),"",('LISTA GESTANTE DO GOOGLE FORMS'!$I10)) -> 9 cpf | I10: =IF(ISBLANK('LISTA GESTANTE DO GOOGLE FORMS'!$J10),"",('LISTA GESTANTE DO GOOGLE FORMS'!$J10)) -> 9 identidade | J10: =IF(ISBLANK('LISTA GESTANTE DO GOOGLE FORMS'!$K10),"",('LISTA GESTANTE DO GOOGLE FORMS'!$K10)) -> 9 D Nascim | K10: =IF(ISBLANK('LISTA GESTANTE DO GOOGLE FORMS'!$L10),"",('LISTA GESTANTE DO GOOGLE FORMS'!$L10)) -> 9 idad | L10: =IF(ISBLANK('LISTA GESTANTE DO GOOGLE FORMS'!$M10),"",('LISTA GESTANTE DO GOOGLE FORMS'!$M10)) -> 9 trab | M10: =IF(ISBLANK('LISTA GESTANTE DO GOOGLE FORMS'!$N10),"",('LISTA GESTANTE DO GOOGLE FORMS'!$N10)) -> 9 Est Civil | N10: =IF(ISBLANK('LISTA GESTANTE DO GOOGLE FORMS'!$O10),"",('LISTA GESTANTE DO GOOGLE FORMS'!$O10)) -> 9 Religiao | O10: =IF(ISBLANK('LISTA GESTANTE DO GOOGLE FORMS'!$P10),"",('LISTA GESTANTE DO GOOGLE FORMS'!$P10)) -> 9 Observações | P10: =IF(ISBLANK('LISTA GESTANTE DO GOOGLE FORMS'!$Q10),"",('LISTA GESTANTE DO GOOGLE FORMS'!$Q10)) -> 9 Endereço | Q10: =IF(ISBLANK('LISTA GESTANTE DO GOOGLE FORMS'!$R10),"",('LISTA GESTANTE DO GOOGLE FORMS'!$R10)) -> 9 Bairro | R10: =IF(ISBLANK('LISTA GESTANTE DO GOOGLE FORMS'!$S10),"",('LISTA GESTANTE DO GOOGLE FORMS'!$S10)) -> 9 cidade | S10: =IF(ISBLANK('LISTA GESTANTE DO GOOGLE FORMS'!$T10),"",('LISTA GESTANTE DO GOOGLE FORMS'!$T10)) -> 9 nome do pai | T10: =IF(ISBLANK('LISTA GESTANTE DO GOOGLE FORMS'!$U10),"",('LISTA GESTANTE DO GOOGLE FORMS'!$U10)) -> 9 NP | U10: =IF(ISBLANK('LISTA GESTANTE DO GOOGLE FORMS'!$V10),"",('LISTA GESTANTE DO GOOGLE FORMS'!$V10)) -> 9 Atendim | V10: =IF(ISBLANK('LISTA GESTANTE DO GOOGLE FORMS'!$W10),"",('LISTA GESTANTE DO GOOGLE FORMS'!$W10)) -> 9 Beneficio | W10: =IF(ISBLANK('LISTA GESTANTE DO GOOGLE FORMS'!$X10),"",('LISTA GESTANTE DO GOOGLE FORMS'!$X10)) -> 9 email | X10: =IF(ISBLANK('LISTA GESTANTE DO GOOGLE FORMS'!$Y10),"",('LISTA GESTANTE DO GOOGLE FORMS'!$Y10)) -> 9 joao
A11: =A10+1 -> 10 | B11: =IF(ISBLANK('LISTA GESTANTE DO GOOGLE FORMS'!$C11),"",('LISTA GESTANTE DO GOOGLE FORMS'!$C11)) -> 10 | C11: =IF(ISBLANK('LISTA GESTANTE DO GOOGLE FORMS'!$D11),"",('LISTA GESTANTE DO GOOGLE FORMS'!$D11)) -> 10 nome da gestante | D11: =IF(ISBLANK('LISTA GESTANTE DO GOOGLE FORMS'!$E11),"",('LISTA GESTANTE DO GOOGLE FORMS'!$E11)) -> 10 telefone | E11: =IF(ISBLANK('LISTA GESTANTE DO GOOGLE FORMS'!$F11),"",('LISTA GESTANTE DO GOOGLE FORMS'!$F11)) -> 10 gest | F11: =IF(ISBLANK('LISTA GESTANTE DO GOOGLE FORMS'!$G11),"",('LISTA GESTANTE DO GOOGLE FORMS'!$G11)) -> 10 parto | G11: =IF(ISBLANK('LISTA GESTANTE DO GOOGLE FORMS'!$H11),"",('LISTA GESTANTE DO GOOGLE FORMS'!$H11)) -> 10 sexo | H11: =IF(ISBLANK('LISTA GESTANTE DO GOOGLE FORMS'!$I11),"",('LISTA GESTANTE DO GOOGLE FORMS'!$I11)) -> 10 cpf | I11: =IF(ISBLANK('LISTA GESTANTE DO GOOGLE FORMS'!$J11),"",('LISTA GESTANTE DO GOOGLE FORMS'!$J11)) -> 10 identidade | J11: =IF(ISBLANK('LISTA GESTANTE DO GOOGLE FORMS'!$K11),"",('LISTA GESTANTE DO GOOGLE FORMS'!$K11)) -> 10 D Nascim | K11: =IF(ISBLANK('LISTA GESTANTE DO GOOGLE FORMS'!$L11),"",('LISTA GESTANTE DO GOOGLE FORMS'!$L11)) -> 10 idad | L11: =IF(ISBLANK('LISTA GESTANTE DO GOOGLE FORMS'!$M11),"",('LISTA GESTANTE DO GOOGLE FORMS'!$M11)) -> 10 trab | M11: =IF(ISBLANK('LISTA GESTANTE DO GOOGLE FORMS'!$N11),"",('LISTA GESTANTE DO GOOGLE FORMS'!$N11)) -> 10 Est Civil | N11: =IF(ISBLANK('LISTA GESTANTE DO GOOGLE FORMS'!$O11),"",('LISTA GESTANTE DO GOOGLE FORMS'!$O11)) -> 10 Religiao | O11: =IF(ISBLANK('LISTA GESTANTE DO GOOGLE FORMS'!$P11),"",('LISTA GESTANTE DO GOOGLE FORMS'!$P11)) -> 10 Observações | P11: =IF(ISBLANK('LISTA GESTANTE DO GOOGLE FORMS'!$Q11),"",('LISTA GESTANTE DO GOOGLE FORMS'!$Q11)) -> 10 Endereço | Q11: =IF(ISBLANK('LISTA GESTANTE DO GOOGLE FORMS'!$R11),"",('LISTA GESTANTE DO GOOGLE FORMS'!$R11)) -> 10 Bairro | R11: =IF(ISBLANK('LISTA GESTANTE DO GOOGLE FORMS'!$S11),"",('LISTA GESTANTE DO GOOGLE FORMS'!$S11)) -> 10 cidade | S11: =IF(ISBLANK('LISTA GESTANTE DO GOOGLE FORMS'!$T11),"",('LISTA GESTANTE DO GOOGLE FORMS'!$T11)) -> 10 nome do pai | T11: =IF(ISBLANK('LISTA GESTANTE DO GOOGLE FORMS'!$U11),"",('LISTA GESTANTE DO GOOGLE FORMS'!$U11)) -> 10 NP | U11: =IF(ISBLANK('LISTA GESTANTE DO GOOGLE FORMS'!$V11),"",('LISTA GESTANTE DO GOOGLE FORMS'!$V11)) -> 10 Atendim | V11: =IF(ISBLANK('LISTA GESTANTE DO GOOGLE FORMS'!$W11),"",('LISTA GESTANTE DO GOOGLE FORMS'!$W11)) -> 10 Beneficio | W11: =IF(ISBLANK('LISTA GESTANTE DO GOOGLE FORMS'!$X11),"",('LISTA GESTANTE DO GOOGLE FORMS'!$X11)) -> 10 email | X11: =IF(ISBLANK('LISTA GESTANTE DO GOOGLE FORMS'!$Y11),"",('LISTA GESTANTE DO GOOGLE FORMS'!$Y11)) -> 10 joao
A12: =A11+1 -> 11 | B12: =IF(ISBLANK('LISTA GESTANTE DO GOOGLE FORMS'!$C12),"",('LISTA GESTANTE DO GOOGLE FORMS'!$C12)) -> 11 | C12: =IF(ISBLANK('LISTA GESTANTE DO GOOGLE FORMS'!$D12),"",('LISTA GESTANTE DO GOOGLE FORMS'!$D12)) -> 11 nome da gestante | D12: =IF(ISBLANK('LISTA GESTANTE DO GOOGLE FORMS'!$E12),"",('LISTA GESTANTE DO GOOGLE FORMS'!$E12)) -> 11 telefone | E12: =IF(ISBLANK('LISTA GESTANTE DO GOOGLE FORMS'!$F12),"",('LISTA GESTANTE DO GOOGLE FORMS'!$F12)) -> 11 gest | F12: =IF(ISBLANK('LISTA GESTANTE DO GOOGLE FORMS'!$G12),"",('LISTA GESTANTE DO GOOGLE FORMS'!$G12)) -> 11 parto | G12: =IF(ISBLANK('LISTA GESTANTE DO GOOGLE FORMS'!$H12),"",('LISTA GESTANTE DO GOOGLE FORMS'!$H12)) -> 11 sexo | H12: =IF(ISBLANK('LISTA GESTANTE DO GOOGLE FORMS'!$I12),"",('LISTA GESTANTE DO GOOGLE FORMS'!$I12)) -> 11 cpf | I12: =IF(ISBLANK('LISTA GESTANTE DO GOOGLE FORMS'!$J12),"",('LISTA GESTANTE DO GOOGLE FORMS'!$J12)) -> 11 identidade | J12: =IF(ISBLANK('LISTA GESTANTE DO GOOGLE FORMS'!$K12),"",('LISTA GESTANTE DO GOOGLE FORMS'!$K12)) -> 11 D Nascim | K12: =IF(ISBLANK('LISTA GESTANTE DO GOOGLE FORMS'!$L12),"",('LISTA GESTANTE DO GOOGLE FORMS'!$L12)) -> 11 idad | L12: =IF(ISBLANK('LISTA GESTANTE DO GOOGLE FORMS'!$M12),"",('LISTA GESTANTE DO GOOGLE FORMS'!$M12)) -> 11 trab | M12: =IF(ISBLANK('LISTA GESTANTE DO GOOGLE FORMS'!$N12),"",('LISTA GESTANTE DO GOOGLE FORMS'!$N12)) -> 11 Est Civil | N12: =IF(ISBLANK('LISTA GESTANTE DO GOOGLE FORMS'!$O12),"",('LISTA GESTANTE DO GOOGLE FORMS'!$O12)) -> 11 Religiao | O12: =IF(ISBLANK('LISTA GESTANTE DO GOOGLE FORMS'!$P12),"",('LISTA GESTANTE DO GOOGLE FORMS'!$P12)) -> 11 Observações | P12: =IF(ISBLANK('LISTA GESTANTE DO GOOGLE FORMS'!$Q12),"",('LISTA GESTANTE DO GOOGLE FORMS'!$Q12)) -> 11 Endereço | Q12: =IF(ISBLANK('LISTA GESTANTE DO GOOGLE FORMS'!$R12),"",('LISTA GESTANTE DO GOOGLE FORMS'!$R12)) -> 11 Bairro | R12: =IF(ISBLANK('LISTA GESTANTE DO GOOGLE FORMS'!$S12),"",('LISTA GESTANTE DO GOOGLE FORMS'!$S12)) -> 11 cidade | S12: =IF(ISBLANK('LISTA GESTANTE DO GOOGLE FORMS'!$T12),"",('LISTA GESTANTE DO GOOGLE FORMS'!$T12)) -> 11 nome do pai | T12: =IF(ISBLANK('LISTA GESTANTE DO GOOGLE FORMS'!$U12),"",('LISTA GESTANTE DO GOOGLE FORMS'!$U12)) -> 11 NP | U12: =IF(ISBLANK('LISTA GESTANTE DO GOOGLE FORMS'!$V12),"",('LISTA GESTANTE DO GOOGLE FORMS'!$V12)) -> 11 Atendim | V12: =IF(ISBLANK('LISTA GESTANTE DO GOOGLE FORMS'!$W12),"",('LISTA GESTANTE DO GOOGLE FORMS'!$W12)) -> 11 Beneficio | W12: =IF(ISBLANK('LISTA GESTANTE DO GOOGLE FORMS'!$X12),"",('LISTA GESTANTE DO GOOGLE FORMS'!$X12)) -> 11 email | X12: =IF(ISBLANK('LISTA GESTANTE DO GOOGLE FORMS'!$Y12),"",('LISTA GESTANTE DO GOOGLE FORMS'!$Y12)) -> 11 joao
A13: =A12+1 -> 12 | B13: =IF(ISBLANK('LISTA GESTANTE DO GOOGLE FORMS'!$C13),"",('LISTA GESTANTE DO GOOGLE FORMS'!$C13)) -> 12 | C13: =IF(ISBLANK('LISTA GESTANTE DO GOOGLE FORMS'!$D13),"",('LISTA GESTANTE DO GOOGLE FORMS'!$D13)) -> 12 nome da gestante | D13: =IF(ISBLANK('LISTA GESTANTE DO GOOGLE FORMS'!$E13),"",('LISTA GESTANTE DO GOOGLE FORMS'!$E13)) -> 12 telefone | E13: =IF(ISBLANK('LISTA GESTANTE DO GOOGLE FORMS'!$F13),"",('LISTA GESTANTE DO GOOGLE FORMS'!$F13)) -> 12 gest | F13: =IF(ISBLANK('LISTA GESTANTE DO GOOGLE FORMS'!$G13),"",('LISTA GESTANTE DO GOOGLE FORMS'!$G13)) -> 12 parto | G13: =IF(ISBLANK('LISTA GESTANTE DO GOOGLE FORMS'!$H13),"",('LISTA GESTANTE DO GOOGLE FORMS'!$H13)) -> 12 sexo | H13: =IF(ISBLANK('LISTA GESTANTE DO GOOGLE FORMS'!$I13),"",('LISTA GESTANTE DO GOOGLE FORMS'!$I13)) -> 12 cpf | I13: =IF(ISBLANK('LISTA GESTANTE DO GOOGLE FORMS'!$J13),"",('LISTA GESTANTE DO GOOGLE FORMS'!$J13)) -> 12 identidade | J13: =IF(ISBLANK('LISTA GESTANTE DO GOOGLE FORMS'!$K13),"",('LISTA GESTANTE DO GOOGLE FORMS'!$K13)) -> 12 D Nascim | K13: =IF(ISBLANK('LISTA GESTANTE DO GOOGLE FORMS'!$L13),"",('LISTA GESTANTE DO GOOGLE FORMS'!$L13)) -> 12 idad | L13: =IF(ISBLANK('LISTA GESTANTE DO GOOGLE FORMS'!$M13),"",('LISTA GESTANTE DO GOOGLE FORMS'!$M13)) -> 12 trab | M13: =IF(ISBLANK('LISTA GESTANTE DO GOOGLE FORMS'!$N13),"",('LISTA GESTANTE DO GOOGLE FORMS'!$N13)) -> 12 Est Civil | N13: =IF(ISBLANK('LISTA GESTANTE DO GOOGLE FORMS'!$O13),"",('LISTA GESTANTE DO GOOGLE FORMS'!$O13)) -> 12 Religiao | O13: =IF(ISBLANK('LISTA GESTANTE DO GOOGLE FORMS'!$P13),"",('LISTA GESTANTE DO GOOGLE FORMS'!$P13)) -> 12 Observações | P13: =IF(ISBLANK('LISTA GESTANTE DO GOOGLE FORMS'!$Q13),"",('LISTA GESTANTE DO GOOGLE FORMS'!$Q13)) -> 12 Endereço | Q13: =IF(ISBLANK('LISTA GESTANTE DO GOOGLE FORMS'!$R13),"",('LISTA GESTANTE DO GOOGLE FORMS'!$R13)) -> 12 Bairro | R13: =IF(ISBLANK('LISTA GESTANTE DO GOOGLE FORMS'!$S13),"",('LISTA GESTANTE DO GOOGLE FORMS'!$S13)) -> 12 cidade | S13: =IF(ISBLANK('LISTA GESTANTE DO GOOGLE FORMS'!$T13),"",('LISTA GESTANTE DO GOOGLE FORMS'!$T13)) -> 12 nome do pai | T13: =IF(ISBLANK('LISTA GESTANTE DO GOOGLE FORMS'!$U13),"",('LISTA GESTANTE DO GOOGLE FORMS'!$U13)) -> 12 NP | U13: =IF(ISBLANK('LISTA GESTANTE DO GOOGLE FORMS'!$V13),"",('LISTA GESTANTE DO GOOGLE FORMS'!$V13)) -> 12 Atendim | V13: =IF(ISBLANK('LISTA GESTANTE DO GOOGLE FORMS'!$W13),"",('LISTA GESTANTE DO GOOGLE FORMS'!$W13)) -> 12 Beneficio | W13: =IF(ISBLANK('LISTA GESTANTE DO GOOGLE FORMS'!$X13),"",('LISTA GESTANTE DO GOOGLE FORMS'!$X13)) -> 12 email | X13: =IF(ISBLANK('LISTA GESTANTE DO GOOGLE FORMS'!$Y13),"",('LISTA GESTANTE DO GOOGLE FORMS'!$Y13)) -> 12 joao
A14: =A13+1 -> 13 | B14: =IF(ISBLANK('LISTA GESTANTE DO GOOGLE FORMS'!$C14),"",('LISTA GESTANTE DO GOOGLE FORMS'!$C14)) -> 13 | C14: =IF(ISBLANK('LISTA GESTANTE DO GOOGLE FORMS'!$D14),"",('LISTA GESTANTE DO GOOGLE FORMS'!$D14)) -> 13 nome da gestante | D14: =IF(ISBLANK('LISTA GESTANTE DO GOOGLE FORMS'!$E14),"",('LISTA GESTANTE DO GOOGLE FORMS'!$E14)) -> 13 telefone | E14: =IF(ISBLANK('LISTA GESTANTE DO GOOGLE FORMS'!$F14),"",('LISTA GESTANTE DO GOOGLE FORMS'!$F14)) -> 13 gest | F14: =IF(ISBLANK('LISTA GESTANTE DO GOOGLE FORMS'!$G14),"",('LISTA GESTANTE DO GOOGLE FORMS'!$G14)) -> 13 parto | G14: =IF(ISBLANK('LISTA GESTANTE DO GOOGLE FORMS'!$H14),"",('LISTA GESTANTE DO GOOGLE FORMS'!$H14)) -> 13 sexo | H14: =IF(ISBLANK('LISTA GESTANTE DO GOOGLE FORMS'!$I14),"",('LISTA GESTANTE DO GOOGLE FORMS'!$I14)) -> 13 cpf | I14: =IF(ISBLANK('LISTA GESTANTE DO GOOGLE FORMS'!$J14),"",('LISTA GESTANTE DO GOOGLE FORMS'!$J14)) -> 13 identidade | J14: =IF(ISBLANK('LISTA GESTANTE DO GOOGLE FORMS'!$K14),"",('LISTA GESTANTE DO GOOGLE FORMS'!$K14)) -> 13 D Nascim | K14: =IF(ISBLANK('LISTA GESTANTE DO GOOGLE FORMS'!$L14),"",('LISTA GESTANTE DO GOOGLE FORMS'!$L14)) -> 13 idad | L14: =IF(ISBLANK('LISTA GESTANTE DO GOOGLE FORMS'!$M14),"",('LISTA GESTANTE DO GOOGLE FORMS'!$M14)) -> 13 trab | M14: =IF(ISBLANK('LISTA GESTANTE DO GOOGLE FORMS'!$N14),"",('LISTA GESTANTE DO GOOGLE FORMS'!$N14)) -> 13 Est Civil | N14: =IF(ISBLANK('LISTA GESTANTE DO GOOGLE FORMS'!$O14),"",('LISTA GESTANTE DO GOOGLE FORMS'!$O14)) -> 13 Religiao | O14: =IF(ISBLANK('LISTA GESTANTE DO GOOGLE FORMS'!$P14),"",('LISTA GESTANTE DO GOOGLE FORMS'!$P14)) -> 13 Observações | P14: =IF(ISBLANK('LISTA GESTANTE DO GOOGLE FORMS'!$Q14),"",('LISTA GESTANTE DO GOOGLE FORMS'!$Q14)) -> 13 Endereço | Q14: =IF(ISBLANK('LISTA GESTANTE DO GOOGLE FORMS'!$R14),"",('LISTA GESTANTE DO GOOGLE FORMS'!$R14)) -> 13 Bairro | R14: =IF(ISBLANK('LISTA GESTANTE DO GOOGLE FORMS'!$S14),"",('LISTA GESTANTE DO GOOGLE FORMS'!$S14)) -> 13 cidade | S14: =IF(ISBLANK('LISTA GESTANTE DO GOOGLE FORMS'!$T14),"",('LISTA GESTANTE DO GOOGLE FORMS'!$T14)) -> 13 nome do pai | T14: =IF(ISBLANK('LISTA GESTANTE DO GOOGLE FORMS'!$U14),"",('LISTA GESTANTE DO GOOGLE FORMS'!$U14)) -> 13 NP | U14: =IF(ISBLANK('LISTA GESTANTE DO GOOGLE FORMS'!$V14),"",('LISTA GESTANTE DO GOOGLE FORMS'!$V14)) -> 13 Atendim | V14: =IF(ISBLANK('LISTA GESTANTE DO GOOGLE FORMS'!$W14),"",('LISTA GESTANTE DO GOOGLE FORMS'!$W14)) -> 13 Beneficio | W14: =IF(ISBLANK('LISTA GESTANTE DO GOOGLE FORMS'!$X14),"",('LISTA GESTANTE DO GOOGLE FORMS'!$X14)) -> 13 email | X14: =IF(ISBLANK('LISTA GESTANTE DO GOOGLE FORMS'!$Y14),"",('LISTA GESTANTE DO GOOGLE FORMS'!$Y14)) -> 13 joao
... A24: =A23+1 -> 23 | B24: =IF(ISBLANK('LISTA GESTANTE DO GOOGLE FORMS'!$C24),"",('LISTA GESTANTE DO GOOGLE FORMS'!$C24)) -> 23 | C24: =IF(ISBLANK('LISTA GESTANTE DO GOOGLE FORMS'!$D24),"",('LISTA GESTANTE DO GOOGLE FORMS'!$D24)) -> 23 nome da gestante | D24: =IF(ISBLANK('LISTA GESTANTE DO GOOGLE FORMS'!$E24),"",('LISTA GESTANTE DO GOOGLE FORMS'!$E24)) -> 23 telefone | E24: =IF(ISBLANK('LISTA GESTANTE DO GOOGLE FORMS'!$F24),"",('LISTA GESTANTE DO GOOGLE FORMS'!$F24)) -> 23 gest | F24: =IF(ISBLANK('LISTA GESTANTE DO GOOGLE FORMS'!$G24),"",('LISTA GESTANTE DO GOOGLE FORMS'!$G24)) -> 23 parto | G24: =IF(ISBLANK('LISTA GESTANTE DO GOOGLE FORMS'!$H24),"",('LISTA GESTANTE DO GOOGLE FORMS'!$H24)) -> 23 sexo | H24: =IF(ISBLANK('LISTA GESTANTE DO GOOGLE FORMS'!$I24),"",('LISTA GESTANTE DO GOOGLE FORMS'!$I24)) -> 23 cpf | I24: =IF(ISBLANK('LISTA GESTANTE DO GOOGLE FORMS'!$J24),"",('LISTA GESTANTE DO GOOGLE FORMS'!$J24)) -> 23 identidade | J24: =IF(ISBLANK('LISTA GESTANTE DO GOOGLE FORMS'!$K24),"",('LISTA GESTANTE DO GOOGLE FORMS'!$K24)) -> 23 D Nascim | K24: =IF(ISBLANK('LISTA GESTANTE DO GOOGLE FORMS'!$L24),"",('LISTA GESTANTE DO GOOGLE FORMS'!$L24)) -> 23 idad | L24: =IF(ISBLANK('LISTA GESTANTE DO GOOGLE FORMS'!$M24),"",('LISTA GESTANTE DO GOOGLE FORMS'!$M24)) -> 23 trab | M24: =IF(ISBLANK('LISTA GESTANTE DO GOOGLE FORMS'!$N24),"",('LISTA GESTANTE DO GOOGLE FORMS'!$N24)) -> 23 Est Civil | N24: =IF(ISBLANK('LISTA GESTANTE DO GOOGLE FORMS'!$O24),"",('LISTA GESTANTE DO GOOGLE FORMS'!$O24)) -> 23 Religiao | O24: =IF(ISBLANK('LISTA GESTANTE DO GOOGLE FORMS'!$P24),"",('LISTA GESTANTE DO GOOGLE FORMS'!$P24)) -> 23 Observações | P24: =IF(ISBLANK('LISTA GESTANTE DO GOOGLE FORMS'!$Q24),"",('LISTA GESTANTE DO GOOGLE FORMS'!$Q24)) -> 23 Endereço | Q24: =IF(ISBLANK('LISTA GESTANTE DO GOOGLE FORMS'!$R24),"",('LISTA GESTANTE DO GOOGLE FORMS'!$R24)) -> 23 Bairro | R24: =IF(ISBLANK('LISTA GESTANTE DO GOOGLE FORMS'!$S24),"",('LISTA GESTANTE DO GOOGLE FORMS'!$S24)) -> 23 cidade | S24: =IF(ISBLANK('LISTA GESTANTE DO GOOGLE FORMS'!$T24),"",('LISTA GESTANTE DO GOOGLE FORMS'!$T24)) -> 23 nome do pai | T24: =IF(ISBLANK('LISTA GESTANTE DO GOOGLE FORMS'!$U24),"",('LISTA GESTANTE DO GOOGLE FORMS'!$U24)) -> 23 NP | U24: =IF(ISBLANK('LISTA GESTANTE DO GOOGLE FORMS'!$V24),"",('LISTA GESTANTE DO GOOGLE FORMS'!$V24)) -> 23 Atendim | V24: =IF(ISBLANK('LISTA GESTANTE DO GOOGLE FORMS'!$W24),"",('LISTA GESTANTE DO GOOGLE FORMS'!$W24)) -> 23 Beneficio | W24: =IF(ISBLANK('LISTA GESTANTE DO GOOGLE FORMS'!$X24),"",('LISTA GESTANTE DO GOOGLE FORMS'!$X24)) -> 23 email | X24: =IF(ISBLANK('LISTA GESTANTE DO GOOGLE FORMS'!$Y24),"",('LISTA GESTANTE DO GOOGLE FORMS'!$Y24)) -> 23 joao
A25: =A24+1 -> 24 | B25: =IF(ISBLANK('LISTA GESTANTE DO GOOGLE FORMS'!$C25),"",('LISTA GESTANTE DO GOOGLE FORMS'!$C25)) -> 24 | C25: =IF(ISBLANK('LISTA GESTANTE DO GOOGLE FORMS'!$D25),"",('LISTA GESTANTE DO GOOGLE FORMS'!$D25)) -> 24 nome da gestante | D25: =IF(ISBLANK('LISTA GESTANTE DO GOOGLE FORMS'!$E25),"",('LISTA GESTANTE DO GOOGLE FORMS'!$E25)) -> 24 telefone | E25: =IF(ISBLANK('LISTA GESTANTE DO GOOGLE FORMS'!$F25),"",('LISTA GESTANTE DO GOOGLE FORMS'!$F25)) -> 24 gest | F25: =IF(ISBLANK('LISTA GESTANTE DO GOOGLE FORMS'!$G25),"",('LISTA GESTANTE DO GOOGLE FORMS'!$G25)) -> 24 parto | G25: =IF(ISBLANK('LISTA GESTANTE DO GOOGLE FORMS'!$H25),"",('LISTA GESTANTE DO GOOGLE FORMS'!$H25)) -> 24 sexo | H25: =IF(ISBLANK('LISTA GESTANTE DO GOOGLE FORMS'!$I25),"",('LISTA GESTANTE DO GOOGLE FORMS'!$I25)) -> 24 cpf | I25: =IF(ISBLANK('LISTA GESTANTE DO GOOGLE FORMS'!$J25),"",('LISTA GESTANTE DO GOOGLE FORMS'!$J25)) -> 24 identidade | J25: =IF(ISBLANK('LISTA GESTANTE DO GOOGLE FORMS'!$K25),"",('LISTA GESTANTE DO GOOGLE FORMS'!$K25)) -> 24 D Nascim | K25: =IF(ISBLANK('LISTA GESTANTE DO GOOGLE FORMS'!$L25),"",('LISTA GESTANTE DO GOOGLE FORMS'!$L25)) -> 24 idad | L25: =IF(ISBLANK('LISTA GESTANTE DO GOOGLE FORMS'!$M25),"",('LISTA GESTANTE DO GOOGLE FORMS'!$M25)) -> 24 trab | M25: =IF(ISBLANK('LISTA GESTANTE DO GOOGLE FORMS'!$N25),"",('LISTA GESTANTE DO GOOGLE FORMS'!$N25)) -> 24 Est Civil | N25: =IF(ISBLANK('LISTA GESTANTE DO GOOGLE FORMS'!$O25),"",('LISTA GESTANTE DO GOOGLE FORMS'!$O25)) -> 24 Religiao | O25: =IF(ISBLANK('LISTA GESTANTE DO GOOGLE FORMS'!$P25),"",('LISTA GESTANTE DO GOOGLE FORMS'!$P25)) -> 24 Observações | P25: =IF(ISBLANK('LISTA GESTANTE DO GOOGLE FORMS'!$Q25),"",('LISTA GESTANTE DO GOOGLE FORMS'!$Q25)) -> 24 Endereço | Q25: =IF(ISBLANK('LISTA GESTANTE DO GOOGLE FORMS'!$R25),"",('LISTA GESTANTE DO GOOGLE FORMS'!$R25)) -> 24 Bairro | R25: =IF(ISBLANK('LISTA GESTANTE DO GOOGLE FORMS'!$S25),"",('LISTA GESTANTE DO GOOGLE FORMS'!$S25)) -> 24 cidade | S25: =IF(ISBLANK('LISTA GESTANTE DO GOOGLE FORMS'!$T25),"",('LISTA GESTANTE DO GOOGLE FORMS'!$T25)) -> 24 nome do pai | T25: =IF(ISBLANK('LISTA GESTANTE DO GOOGLE FORMS'!$U25),"",('LISTA GESTANTE DO GOOGLE FORMS'!$U25)) -> 24 NP | U25: =IF(ISBLANK('LISTA GESTANTE DO GOOGLE FORMS'!$V25),"",('LISTA GESTANTE DO GOOGLE FORMS'!$V25)) -> 24 Atendim | V25: =IF(ISBLANK('LISTA GESTANTE DO GOOGLE FORMS'!$W25),"",('LISTA GESTANTE DO GOOGLE FORMS'!$W25)) -> 24 Beneficio | W25: =IF(ISBLANK('LISTA GESTANTE DO GOOGLE FORMS'!$X25),"",('LISTA GESTANTE DO GOOGLE FORMS'!$X25)) -> 24 email | X25: =IF(ISBLANK('LISTA GESTANTE DO GOOGLE FORMS'!$Y25),"",('LISTA GESTANTE DO GOOGLE FORMS'!$Y25)) -> 24 joao | AI25: 0
A26: =A25+1 -> 25 | B26: =IF(ISBLANK('LISTA GESTANTE DO GOOGLE FORMS'!$C26),"",('LISTA GESTANTE DO GOOGLE FORMS'!$C26)) -> 25 | C26: =IF(ISBLANK('LISTA GESTANTE DO GOOGLE FORMS'!$D26),"",('LISTA GESTANTE DO GOOGLE FORMS'!$D26)) -> 25 nome da gestante | D26: =IF(ISBLANK('LISTA GESTANTE DO GOOGLE FORMS'!$E26),"",('LISTA GESTANTE DO GOOGLE FORMS'!$E26)) -> 25 telefone | E26: =IF(ISBLANK('LISTA GESTANTE DO GOOGLE FORMS'!$F26),"",('LISTA GESTANTE DO GOOGLE FORMS'!$F26)) -> 25 gest | F26: =IF(ISBLANK('LISTA GESTANTE DO GOOGLE FORMS'!$G26),"",('LISTA GESTANTE DO GOOGLE FORMS'!$G26)) -> 25 parto | G26: =IF(ISBLANK('LISTA GESTANTE DO GOOGLE FORMS'!$H26),"",('LISTA GESTANTE DO GOOGLE FORMS'!$H26)) -> 25 sexo | H26: =IF(ISBLANK('LISTA GESTANTE DO GOOGLE FORMS'!$I26),"",('LISTA GESTANTE DO GOOGLE FORMS'!$I26)) -> 25 cpf | I26: =IF(ISBLANK('LISTA GESTANTE DO GOOGLE FORMS'!$J26),"",('LISTA GESTANTE DO GOOGLE FORMS'!$J26)) -> 25 identidade | J26: =IF(ISBLANK('LISTA GESTANTE DO GOOGLE FORMS'!$K26),"",('LISTA GESTANTE DO GOOGLE FORMS'!$K26)) -> 25 D Nascim | K26: =IF(ISBLANK('LISTA GESTANTE DO GOOGLE FORMS'!$L26),"",('LISTA GESTANTE DO GOOGLE FORMS'!$L26)) -> 25 idad | L26: =IF(ISBLANK('LISTA GESTANTE DO GOOGLE FORMS'!$M26),"",('LISTA GESTANTE DO GOOGLE FORMS'!$M26)) -> 25 trab | M26: =IF(ISBLANK('LISTA GESTANTE DO GOOGLE FORMS'!$N26),"",('LISTA GESTANTE DO GOOGLE FORMS'!$N26)) -> 25 Est Civil | N26: =IF(ISBLANK('LISTA GESTANTE DO GOOGLE FORMS'!$O26),"",('LISTA GESTANTE DO GOOGLE FORMS'!$O26)) -> 25 Religiao | O26: =IF(ISBLANK('LISTA GESTANTE DO GOOGLE FORMS'!$P26),"",('LISTA GESTANTE DO GOOGLE FORMS'!$P26)) -> 25 Observações | P26: =IF(ISBLANK('LISTA GESTANTE DO GOOGLE FORMS'!$Q26),"",('LISTA GESTANTE DO GOOGLE FORMS'!$Q26)) -> 25 Endereço | Q26: =IF(ISBLANK('LISTA GESTANTE DO GOOGLE FORMS'!$R26),"",('LISTA GESTANTE DO GOOGLE FORMS'!$R26)) -> 25 Bairro | R26: =IF(ISBLANK('LISTA GESTANTE DO GOOGLE FORMS'!$S26),"",('LISTA GESTANTE DO GOOGLE FORMS'!$S26)) -> 25 cidade | S26: =IF(ISBLANK('LISTA GESTANTE DO GOOGLE FORMS'!$T26),"",('LISTA GESTANTE DO GOOGLE FORMS'!$T26)) -> 25 nome do pai | T26: =IF(ISBLANK('LISTA GESTANTE DO GOOGLE FORMS'!$U26),"",('LISTA GESTANTE DO GOOGLE FORMS'!$U26)) -> 25 NP | U26: =IF(ISBLANK('LISTA GESTANTE DO GOOGLE FORMS'!$V26),"",('LISTA GESTANTE DO GOOGLE FORMS'!$V26)) -> 25 Atendim | V26: =IF(ISBLANK('LISTA GESTANTE DO GOOGLE FORMS'!$W26),"",('LISTA GESTANTE DO GOOGLE FORMS'!$W26)) -> 25 Beneficio | W26: =IF(ISBLANK('LISTA GESTANTE DO GOOGLE FORMS'!$X26),"",('LISTA GESTANTE DO GOOGLE FORMS'!$X26)) -> 25 email | X26: =IF(ISBLANK('LISTA GESTANTE DO GOOGLE FORMS'!$Y26),"",('LISTA GESTANTE DO GOOGLE FORMS'!$Y26)) -> 25 joao
A27: =A26+1 -> 26 | B27: =IF(ISBLANK('LISTA GESTANTE DO GOOGLE FORMS'!$C27),"",('LISTA GESTANTE DO GOOGLE FORMS'!$C27)) -> 26 | C27: =IF(ISBLANK('LISTA GESTANTE DO GOOGLE FORMS'!$D27),"",('LISTA GESTANTE DO GOOGLE FORMS'!$D27)) -> 26 nome da gestante | D27: =IF(ISBLANK('LISTA GESTANTE DO GOOGLE FORMS'!$E27),"",('LISTA GESTANTE DO GOOGLE FORMS'!$E27)) -> 26 telefone | E27: =IF(ISBLANK('LISTA GESTANTE DO GOOGLE FORMS'!$F27),"",('LISTA GESTANTE DO GOOGLE FORMS'!$F27)) -> 26 gest | F27: =IF(ISBLANK('LISTA GESTANTE DO GOOGLE FORMS'!$G27),"",('LISTA GESTANTE DO GOOGLE FORMS'!$G27)) -> 26 parto | G27: =IF(ISBLANK('LISTA GESTANTE DO GOOGLE FORMS'!$H27),"",('LISTA GESTANTE DO GOOGLE FORMS'!$H27)) -> 26 sexo | H27: =IF(ISBLANK('LISTA GESTANTE DO GOOGLE FORMS'!$I27),"",('LISTA GESTANTE DO GOOGLE FORMS'!$I27)) -> 26 cpf | I27: =IF(ISBLANK('LISTA GESTANTE DO GOOGLE FORMS'!$J27),"",('LISTA GESTANTE DO GOOGLE FORMS'!$J27)) -> 26 identidade | J27: =IF(ISBLANK('LISTA GESTANTE DO GOOGLE FORMS'!$K27),"",('LISTA GESTANTE DO GOOGLE FORMS'!$K27)) -> 26 D Nascim | K27: =IF(ISBLANK('LISTA GESTANTE DO GOOGLE FORMS'!$L27),"",('LISTA GESTANTE DO GOOGLE FORMS'!$L27)) -> 26 idad | L27: =IF(ISBLANK('LISTA GESTANTE DO GOOGLE FORMS'!$M27),"",('LISTA GESTANTE DO GOOGLE FORMS'!$M27)) -> 26 trab | M27: =IF(ISBLANK('LISTA GESTANTE DO GOOGLE FORMS'!$N27),"",('LISTA GESTANTE DO GOOGLE FORMS'!$N27)) -> 26 Est Civil | N27: =IF(ISBLANK('LISTA GESTANTE DO GOOGLE FORMS'!$O27),"",('LISTA GESTANTE DO GOOGLE FORMS'!$O27)) -> 26 Religiao | O27: =IF(ISBLANK('LISTA GESTANTE DO GOOGLE FORMS'!$P27),"",('LISTA GESTANTE DO GOOGLE FORMS'!$P27)) -> 26 Observações | P27: =IF(ISBLANK('LISTA GESTANTE DO GOOGLE FORMS'!$Q27),"",('LISTA GESTANTE DO GOOGLE FORMS'!$Q27)) -> 26 Endereço | Q27: =IF(ISBLANK('LISTA GESTANTE DO GOOGLE FORMS'!$R27),"",('LISTA GESTANTE DO GOOGLE FORMS'!$R27)) -> 26 Bairro | R27: =IF(ISBLANK('LISTA GESTANTE DO GOOGLE FORMS'!$S27),"",('LISTA GESTANTE DO GOOGLE FORMS'!$S27)) -> 26 cidade | S27: =IF(ISBLANK('LISTA GESTANTE DO GOOGLE FORMS'!$T27),"",('LISTA GESTANTE DO GOOGLE FORMS'!$T27)) -> 26 nome do pai | T27: =IF(ISBLANK('LISTA GESTANTE DO GOOGLE FORMS'!$U27),"",('LISTA GESTANTE DO GOOGLE FORMS'!$U27)) -> 26 NP | U27: =IF(ISBLANK('LISTA GESTANTE DO GOOGLE FORMS'!$V27),"",('LISTA GESTANTE DO GOOGLE FORMS'!$V27)) -> 26 Atendim | V27: =IF(ISBLANK('LISTA GESTANTE DO GOOGLE FORMS'!$W27),"",('LISTA GESTANTE DO GOOGLE FORMS'!$W27)) -> 26 Beneficio | W27: =IF(ISBLANK('LISTA GESTANTE DO GOOGLE FORMS'!$X27),"",('LISTA GESTANTE DO GOOGLE FORMS'!$X27)) -> 26 email | X27: =IF(ISBLANK('LISTA GESTANTE DO GOOGLE FORMS'!$Y27),"",('LISTA GESTANTE DO GOOGLE FORMS'!$Y27)) -> 26 joao
A28: =A27+1 -> 27 | B28: =IF(ISBLANK('LISTA GESTANTE DO GOOGLE FORMS'!$C28),"",('LISTA GESTANTE DO GOOGLE FORMS'!$C28)) -> 27 | C28: =IF(ISBLANK('LISTA GESTANTE DO GOOGLE FORMS'!$D28),"",('LISTA GESTANTE DO GOOGLE FORMS'!$D28)) -> 27 nome da gestante | D28: =IF(ISBLANK('LISTA GESTANTE DO GOOGLE FORMS'!$E28),"",('LISTA GESTANTE DO GOOGLE FORMS'!$E28)) -> 27 telefone | E28: =IF(ISBLANK('LISTA GESTANTE DO GOOGLE FORMS'!$F28),"",('LISTA GESTANTE DO GOOGLE FORMS'!$F28)) -> 27 gest | F28: =IF(ISBLANK('LISTA GESTANTE DO GOOGLE FORMS'!$G28),"",('LISTA GESTANTE DO GOOGLE FORMS'!$G28)) -> 27 parto | G28: =IF(ISBLANK('LISTA GESTANTE DO GOOGLE FORMS'!$H28),"",('LISTA GESTANTE DO GOOGLE FORMS'!$H28)) -> 27 sexo | H28: =IF(ISBLANK('LISTA GESTANTE DO GOOGLE FORMS'!$I28),"",('LISTA GESTANTE DO GOOGLE FORMS'!$I28)) -> 27 cpf | I28: =IF(ISBLANK('LISTA GESTANTE DO GOOGLE FORMS'!$J28),"",('LISTA GESTANTE DO GOOGLE FORMS'!$J28)) -> 27 identidade | J28: =IF(ISBLANK('LISTA GESTANTE DO GOOGLE FORMS'!$K28),"",('LISTA GESTANTE DO GOOGLE FORMS'!$K28)) -> 27 D Nascim | K28: =IF(ISBLANK('LISTA GESTANTE DO GOOGLE FORMS'!$L28),"",('LISTA GESTANTE DO GOOGLE FORMS'!$L28)) -> 27 idad | L28: =IF(ISBLANK('LISTA GESTANTE DO GOOGLE FORMS'!$M28),"",('LISTA GESTANTE DO GOOGLE FORMS'!$M28)) -> 27 trab | M28: =IF(ISBLANK('LISTA GESTANTE DO GOOGLE FORMS'!$N28),"",('LISTA GESTANTE DO GOOGLE FORMS'!$N28)) -> 27 Est Civil | N28: =IF(ISBLANK('LISTA GESTANTE DO GOOGLE FORMS'!$O28),"",('LISTA GESTANTE DO GOOGLE FORMS'!$O28)) -> 27 Religiao | O28: =IF(ISBLANK('LISTA GESTANTE DO GOOGLE FORMS'!$P28),"",('LISTA GESTANTE DO GOOGLE FORMS'!$P28)) -> 27 Observações | P28: =IF(ISBLANK('LISTA GESTANTE DO GOOGLE FORMS'!$Q28),"",('LISTA GESTANTE DO GOOGLE FORMS'!$Q28)) -> 27 Endereço | Q28: =IF(ISBLANK('LISTA GESTANTE DO GOOGLE FORMS'!$R28),"",('LISTA GESTANTE DO GOOGLE FORMS'!$R28)) -> 27 Bairro | R28: =IF(ISBLANK('LISTA GESTANTE DO GOOGLE FORMS'!$S28),"",('LISTA GESTANTE DO GOOGLE FORMS'!$S28)) -> 27 cidade | S28: =IF(ISBLANK('LISTA GESTANTE DO GOOGLE FORMS'!$T28),"",('LISTA GESTANTE DO GOOGLE FORMS'!$T28)) -> 27 nome do pai | T28: =IF(ISBLANK('LISTA GESTANTE DO GOOGLE FORMS'!$U28),"",('LISTA GESTANTE DO GOOGLE FORMS'!$U28)) -> 27 NP | U28: =IF(ISBLANK('LISTA GESTANTE DO GOOGLE FORMS'!$V28),"",('LISTA GESTANTE DO GOOGLE FORMS'!$V28)) -> 27 Atendim | V28: =IF(ISBLANK('LISTA GESTANTE DO GOOGLE FORMS'!$W28),"",('LISTA GESTANTE DO GOOGLE FORMS'!$W28)) -> 27 Beneficio | W28: =IF(ISBLANK('LISTA GESTANTE DO GOOGLE FORMS'!$X28),"",('LISTA GESTANTE DO GOOGLE FORMS'!$X28)) -> 27 email | X28: =IF(ISBLANK('LISTA GESTANTE DO GOOGLE FORMS'!$Y28),"",('LISTA GESTANTE DO GOOGLE FORMS'!$Y28)) -> 27 joao
